Workbook

Sheet ปก
D3: ร่าง-แบบประเมินสถานประกอบการตามเกณฑ์ HICM V2025
D5: Health Industrial Community Model (HICM) Version 2025
D7: แบบประเมินบูรณาการสุขภาวะองค์กรอุตสาหกรรมและชุมชนเพื่อการพัฒนาอย่างยั่งยืน
D12: โครงการการพัฒนาโมเดลชุมชนอุตสาหกรรมสุขภาวะ
D13: เพื่อการเสริมสร้างสุขภาพคนวัยทำงานแบบบูรณาการและยั่งยืน
D15: Development of Health Industrial Community Model (HICM)
D16: for Integrated and Sustainable Working-Age Health Promotion Project
D21: จัดทำโดย:
D22: คณะผู้วิจัยโครงการการพัฒนาโมเดลชุมชนอุตสาหกรรมสุขภาวะ
D24: เพื่อการเสริมสร้างสุขภาพคนวัยทำงานแบบบูรณาการและยั่งยืน
D28: พ.ศ. 2568 (2025)

Sheet ส่วนที่ 1
A1: ส่วนที่ 1: บทนำและหลักการ
A2: 1.1 วัตถุประสงค์ของแบบประเมิน
A3: แบบประเมิน HICM V2025 จัดทำขึ้นเพื่อเป็นเครื่องมือในการประเมินและพัฒนาสถานประกอบการอุตสาหกรรมให้เป็นองค์กรสุขภาวะอย่างยั่งยืน โดยมุ่งเน้นการบูรณาการการส่งเสริมสุขภาพ ความปลอดภัยในการทำงาน การมีส่วนร่วมกับชุมชน และการบริหารจัดการที่มีประสิทธิภาพ เพื่อสร้างสภาพแวดล้อมการทำงานที่ดี และส่งเสริมคุณภาพชีวิตที่ดีของคนทำงานและชุมชนโดยรอบ
B4: วัตถุประสงค์เชิงกลยุทธ์:
B5: • เพื่อประเมินระดับการพัฒนาสุขภาวะองค์กรอย่างครบวงจร
B6: • เพื่อกำหนดแนวทางการพัฒนาที่ชัดเจนและวัดผลได้
B7: • เพื่อสร้างมาตรฐานองค์กรสุขภาวะในภาคอุตสาหกรรมไทย
B8: • เพื่อส่งเสริมความรับผิดชอบต่อสังคมและการพัฒนาที่ยั่งยืน (CSR & ESG)
A9: 1.2 หลักคิด HICM และกรอบแนวคิด
A10: Health Industrial Community Model (HICM) เป็นกรอบแนวคิดที่พัฒนาขึ้นจากการบูรณาการหลักการสร้างเสริมสุขภาพ (Health Promotion) ตามแนวทางขององค์การอนามัยโลก (WHO) หลักการอาชีวอนามัยและความปลอดภัย (Occupational Health and Safety) ตามมาตรฐาน ISO 45001:2018 แนวคิดการพัฒนาชุมชนแบบมีส่วนร่วม (Community-Based Participatory Development) และหลักการบริหารจัดการเพื่อความยั่งยืน (Sustainability Management) ตาม SDGs และ ESG Framework
B11: กรอบแนวคิด 4 Pillars ของ HICM:
B12: · Pillar 1: Health Promotion (H1) - การส่งเสริมสุขภาพ
B13: มุ่งเน้นการสร้างเสริมสุขภาพแบบองค์รวม ครอบคลุมสุขภาพกาย จิต สังคม และปัญญา ตามหลักการ Ottawa Charter for Health Promotion (WHO, 1986) และแนวทาง Healthy Workplace Framework (WHO, 2010) รวมถึงการป้องกันและควบคุมโรคไม่ติดต่อเรื้อรัง (NCDs) ซึ่งเป็นปัญหาสุขภาพสำคัญของคนทำงานไทย
B14: · Pillar 2: Industrial Safety & Environment (I2) - ความปลอดภัยและสิ่งแวดล้อม
B15: มุ่งเน้นการจัดการความปลอดภัยอาชีวอนามัยและสิ่งแวดล้อมในการทำงานตามมาตรฐานสากล ISO 45001:2018 (Occupational Health and Safety Management Systems), ISO 14001:2015 (Environmental Management Systems) และพระราชบัญญัติความปลอดภัย อาชีวอนามัย และสภาพแวดล้อมในการทำงาน พ.ศ. 2554
B16: · Pillar 3: Community Engagement (C3) - การมีส่วนร่วมกับชุมชน
B17: มุ่งเน้นการสร้างความสัมพันธ์เชิงบวกระหว่างสถานประกอบการกับชุมชนโดยรอบ ตามแนวคิด Shared Value Creation และ Social License to Operate เชื่อมโยงกับเป้าหมายการพัฒนาที่ยั่งยืน (SDGs) โดยเฉพาะเป้าหมายที่ 3 (สุขภาพและความเป็นอยู่ที่ดี), เป้าหมายที่ 11 (เมืองและชุมชนที่ยั่งยืน) และเป้าหมายที่ 17 (ความร่วมมือเพื่อการพัฒนา)
B18: · Pillar 4: Management & Sustainability (M4) - การบริหารจัดการและความยั่งยืน
B19: มุ่งเน้นการบริหารจัดการองค์กรแบบบูรณาการที่เชื่อมโยงกับกลยุทธ์ระยะยาว ตามหลักการ ESG (Environmental, Social, and Governance) และ GRI Standards (Global Reporting Initiative) เพื่อความโปร่งใส ตรวจสอบได้ และยั่งยืน
A20: 1.3 แนวทางการใช้แบบประเมิน
A21: แบบประเมิน HICM V2025 ออกแบบให้สถานประกอบการสามารถประเมินตนเอง (Self-Assessment) โดยใช้หลักฐานเชิงประจักษ์ (Evidence-Based Assessment) ประกอบการพิจารณา และสามารถนำผลการประเมินไปพัฒนาปรับปรุงอย่างต่อเนื่อง
B22: ขั้นตอนการประเมิน:
B23: 1. จัดตั้งคณะทำงาน: แต่งตั้งคณะทำงานประเมิน HICM ประกอบด้วยผู้แทนจากทุกหน่วยงานที่เกี่ยวข้อง
B24: 2. รวบรวมหลักฐาน: จัดเตรียมเอกสาร ข้อมูล และหลักฐานประกอบการประเมินตามที่กำหนดในแต่ละตัวชี้วัด
B25: 3. ประเมินตนเอง: ประเมินตามตัวชี้วัดทั้ง 60 ข้อ โดยให้คะแนนตามระดับ 0-1.0 พร้อมระบุหลักฐาน
B26: 4. ตรวจสอบและยืนยัน: ตรวจสอบความถูกต้องของการประเมินและหลักฐานประกอบ
B27: 5. สรุปผลและวางแผน: สรุปผลคะแนนรวม วิเคราะห์จุดแข็ง-จุดอ่อน และวางแผนพัฒนาปรับปรุง
B28: 6. รายงานและเผยแพร่: จัดทำรายงานผลการประเมินและแผนพัฒนา เพื่อเผยแพร่และสื่อสาร
A29: 1.4 หลักวิชาการและเอกสารอ้างอิง
B30: แบบประเมิน HICM V2025 พัฒนาขึ้นบนพื้นฐานหลักวิชาการและเอกสารอ้างอิงที่สำคัญ ดังนี้:
B31: มาตรฐานและแนวปฏิบัติสากล
B32: • WHO Healthy Workplace Framework and Model (2010)
B33: • ISO 45001:2018 - Occupational Health and Safety Management Systems
B34: • ISO 14001:2015 - Environmental Management Systems
B35: • ILO Convention on Occupational Safety and Health (C155)
B36: • GRI Standards - Global Reporting Initiative
B37: • UN Sustainable Development Goals (SDGs) - เป้าหมายที่ 3, 8, 11, 17
B38: กฎหมายและข้อกำหนดของไทย
B39: • พระราชบัญญัติความปลอดภัย อาชีวอนามัย และสภาพแวดล้อมในการทำงาน พ.ศ. 2554
B40: • พระราชบัญญัติส่งเสริมและพัฒนาคุณภาพชีวิตคนพิการ พ.ศ. 2550
...

Sheet ส่วนที่ 2
A1: ส่วนที่ 2: โครงสร้างและระบบคะแนน
A2: 2.1 โครงสร้าง 4 Pillars
A3: Pillar | B3: ชื่อหมวด | C3: จำนวนตัวชี้วัด | D3: น้ำหนักคะแนน
A4: Pillar 1 (H1) | B4: Health Promotion (การส่งเสริมสุขภาพ) | C4: 15 | D4: 300
A5: Pillar 2 (I2) | B5: Industrial Safety & Environment (ความปลอดภัยและสิ่งแวดล้อม) | C5: 15 | D5: 300
A6: Pillar 3 (C3) | B6: Community Engagement (การมีส่วนร่วมกับชุมชน) | C6: 15 | D6: 200
A7: Pillar 4 (M4) | B7: Management & Sustainability (การบริหารจัดการและความยั่งยืน) | C7: 15 | D7: 200
A8: คะแนนรวมทั้งหมด: 1,000 คะแนน
A10: 2.2 ระบบคะแนนและเกณฑ์การประเมิน
A11: แบบประเมิน HICM V2025 ใช้ระบบคะแนนแบบก้าวหน้า (Progressive Scoring) ในระดับ 0-1.0 เพื่อแสดงถึงระดับการพัฒนาที่ชัดเจนและวัดผลได้ โดยแต่ละตัวชี้วัดมีคะแนนเต็ม 20 คะแนน (60 ตัวชี้วัด x 20 = 1,200 คะแนน จากนั้นปรับสัดส่วนตามน้ำหนักของแต่ละ Pillar)
A12: ระดับคะแนน | B12: คำนิยาม | C12: ลักษณะการดำเนินงาน
A13: 0 | B13: ไม่มีการดำเนินงาน | C13: ไม่มีนโยบาย ไม่มีการดำเนินการใดๆ หรือไม่มีหลักฐาน
A14: 0.25 | B14: เริ่มดำเนินการเบื้องต้น | C14: มีการเริ่มต้นดำเนินการ มีนโยบายหรือแผนเบื้องต้น แต่ยังไม่มีหลักฐานชัดเจน
A15: 0.5 | B15: มีการดำเนินงานบางส่วนพร้อมหลักฐาน | C15: มีการดำเนินงานอย่างจริงจัง มีหลักฐานประกอบ แต่ยังไม่ครอบคลุมหรือไม่สม่ำเสมอ
A16: 0.75 | B16: ดำเนินงานครอบคลุมและมีการติดตาม | C16: มีการดำเนินงานอย่างครอบคลุม มีระบบติดตามประเมินผล มีการปรับปรุงตามผลการติดตาม
A17: 1 | B17: ดำเนินงานครบถ้วนและยั่งยืน | C17: มีการดำเนินงานครบถ้วนตามเกณฑ์ มีระบบประเมินผลและพัฒนาอย่างต่อเนื่อง มีผลลัพธ์ที่ดีและยั่งยืน
A19: 2.3 ระดับการพัฒนาและการรับรอง (HICM Recognition Levels)
A20: สถานประกอบการที่ผ่านการประเมิน HICM จะได้รับการจัดระดับตามคะแนนรวม เพื่อสะท้อนถึงระดับการพัฒนาและเป็นแรงจูงใจในการพัฒนาอย่างต่อเนื่อง
A21: ระดับ | B21: คะแนน | C21: ชื่อระดับ | D21: ความหมาย
A22: Level 1 | B22: < 600 | C22: เริ่มต้น (Emerging) | D22: องค์กรเริ่มให้ความสำคัญกับสุขภาวะ มีพื้นฐานบางส่วน
A23: Level 2 | B23: 600-699 | C23: กำลังพัฒนา (Developing) | D23: องค์กรมีระบบพื้นฐานครบ กำลังพัฒนาให้ครอบคลุม
A24: Level 3 | B24: 700-799 | C24: พัฒนาดี (Performing) | D24: องค์กรมีระบบที่ดี มีการดำเนินงานอย่างมีประสิทธิภาพ
A25: Level 4 | B25: 800-899 | C25: เป็นเลิศ (Excellence) | D25: องค์กรมีมาตรฐานสูง เป็นแบบอย่างที่ดี
A26: Level 5 | B26: 900-1000 | C26: ระดับโลก (World-Class) | D26: องค์กรมีมาตรฐานระดับสากล เป็นต้นแบบแห่งการเรียนรู้
A27: หมายเหตุ: สถานประกอบการที่ได้คะแนนตั้งแต่ Level 3 ขึ้นไป สามารถขอรับการรับรอง HICM Recognition จากหน่วยงานที่เกี่ยวข้อง เพื่อใช้ในการประชาสัมพันธ์และสร้างภาพลักษณ์องค์กร

Sheet ส่วนที่ 3 (H)
A1: Pillar 1: Health Promotion (H1) - การส่งเสริมสุขภาพ
A4: การประเมินผลการดำเนินการ (ประกอบด้วย จำนวน 15 ตัวชี้วัด / น้ำหนักคะแนน 300 คะแนน) | D4: กรอบแนวคิด : มุ่งเน้นการสร้างเสริมสุขภาพแบบองค์รวม ครอบคลุมสุขภาพกาย จิต สังคม และปัญญา ตามหลักการ Ottawa Charter for Health Promotion (WHO, 1986) และแนวทาง Healthy Workplace Framework (WHO, 2010) รวมถึงการป้องกันและควบคุมโรคไม่ติดต่อเรื้อรัง (NCDs) ซึ่งเป็นปัญหาสุขภาพสำคัญของคนทำงานไทย
A7: สรุปผลคะแนน
A8: Health Promotion (H1) - การส่งเสริมสุขภาพ (คะแนนเต็ม = 300 คะแนน)
B9: คะแนนที่ได้ : | C9: =H31 -> 250
B10: ร้อยละ (%) : | C10: =(C9/300)*100 -> 83.333333
A14: ตัวชี้วัด | B14: เกณฑ์ | C14: คำอธิบายตัวชี้วัด | D14: เกณฑ์การประเมิน | E14: การประเมินโดยตนเอง | I14: การประเมินโดยกรรมการ
E15: ผลการดำเนินงาน | F15: หลักฐานประกอบ | G15: ระดับการประเมินตนเอง | H15: คะแนนที่ได้ | I15: ระดับการประเมินจากกรรมการ | J15: คะแนนที่ได้ | K15: ข้อเสนอแนะในการพัฒนา
A16: Pillar 1: Health Promotion (H1) - การส่งเสริมสุขภาพ | B16: H1.1: นโยบายสุขภาวะองค์กร (Organizational Health Policy) | C16: สถานประกอบการมีนโยบายสุขภาวะที่ชัดเจน เป็นลายลักษณ์อักษร ประกาศให้พนักงานทราบทั่วกัน และบูรณาการเข้ากับยุทธศาสตร์องค์กร มีการทบทวนปรับปรุงเป็นประจำทุกปี | D16: • ระดับ 0: ไม่มีนโยบายสุขภาวะเป็นลายลักษณ์อักษร • ระดับ 0.25: มีนโยบายสุขภาวะเป็นลายลักษณ์อักษร แต่ยังไม่ประกาศอย่างเป็นทางการ • ระดับ 0.50: มีนโยบายสุขภาวะที่ประกาศอย่างเป็นทางการ และแจ้งให้พนักงานทราบ • ระดับ 0.75: มีนโยบายสุขภาวะที่บูรณาการกับยุทธศาสตร์องค์กร มีการทบทวนเป็นประจำ • ระดับ 1.0: มีนโยบายสุขภาวะที่ครอบคลุม บูรณาการกับยุทธศาสตร์ มีการทบทวนและปรับปรุงต่อเนื่อง มีการวัดผลสัมฤทธิ์ | G16: 0.25 | H16: =G16*20 -> 5 | I16: 0.5 | J16: =I16*20 -> 10
B17: H1.2: แผนปฏิบัติการสุขภาวะประจำปี (Annual Health Action Plan) | C17: สถานประกอบการมีแผนปฏิบัติการส่งเสริมสุขภาพประจำปีที่ชัดเจน มีกิจกรรมครอบคลุม มีงบประมาณและผู้รับผิดชอบที่ชัดเจน และมีการติดตามประเมินผล | D17: • ระดับ 0: ไม่มีแผนปฏิบัติการด้านสุขภาวะ • ระดับ 0.25: มีแผนปฏิบัติการเบื้องต้น แต่ยังไม่มีรายละเอียดครบถ้วน • ระดับ 0.50: มีแผนปฏิบัติการที่ชัดเจน มีงบประมาณและผู้รับผิดชอบ • ระดับ 0.75: มีแผนปฏิบัติการครอบคลุมทุกมิติของสุขภาวะ มีการติดตามผลเป็นระยะ • ระดับ 1.0: มีแผนปฏิบัติการที่บูรณาการและครบวงจร มีการประเมินผลและปรับปรุงอย่างต่อเนื่อง | G17: 0.5 | H17: =G17*20 -> 10 | I17: 1 | J17: =I17*20 -> 20
B18: H1.3: ระบบข้อมูลสุขภาพพนักงาน (Employee Health Information System) | C18: สถานประกอบการมีระบบฐานข้อมูลสุขภาพพนักงานที่ครบถ้วน ปลอดภัย สามารถวิเคราะห์และนำไปใช้ในการวางแผนสุขภาพ โดยเคารพความเป็นส่วนตัวและปฏิบัติตาม พ.ร.บ. คุ้มครองข้อมูลส่วนบุคคล | D18: • ระดับ 0: ไม่มีระบบข้อมูลสุขภาพ หรือมีแต่ไม่เป็นระบบ • ระดับ 0.25: มีการเก็บข้อมูลสุขภาพพื้นฐาน แต่ยังไม่เป็นระบบ • ระดับ 0.50: มีระบบฐานข้อมูลสุขภาพที่เป็นระบบ มีการรักษาความลับ • ระดับ 0.75: มีระบบข้อมูลที่สามารถวิเคราะห์และออกรายงานได้ มีการอัพเดทสม่ำเสมอ • ระดับ 1.0: มีระบบข้อมูลที่ทันสมัย สามารถบูรณาการกับระบบอื่น ใช้ในการตัดสินใจเชิงนโยบาย | G18: 0.75 | H18: =G18*20 -> 15 | I18: 1 | J18: =I18*20 -> 20
B19: H1.4: การตรวจสุขภาพและติดตามผล (Health Examination and Follow-up) | C19: สถานประกอบการจัดให้มีการตรวจสุขภาพประจำปีครบทุกกลุ่มเสี่ยง มีการคัดกรอง NCDs และอาชีวอนามัย มีระบบติดตามผลผู้ป่วยและผู้มีปัจจัยเสี่ยงอย่างต่อเนื่อง | D19: • ระดับ 0: ไม่มีการตรวจสุขภาพพนักงาน • ระดับ 0.25: มีการตรวจสุขภาพพนักงานบางส่วน แต่ยังไม่ครอบคลุม • ระดับ 0.50: มีการตรวจสุขภาพครบทุกกลุ่มตามกฎหมาย มีรายงานผล • ระดับ 0.75: มีการตรวจสุขภาพครอบคลุมกลุ่มเสี่ยง มีการติดตามผลผู้ป่วยและผู้เสี่ยง • ระดับ 1.0: มีการตรวจสุขภาพครบถ้วน มีระบบติดตามผลต่อเนื่อง มีการวิเคราะห์และป้องกันเชิงรุก | G19: 1 | H19: =G19*20 -> 20 | I19: 1 | J19: =I19*20 -> 20
B20: H1.5: บริการให้คำปรึกษาและ EAP (Employee Assistance Program) | C20: สถานประกอบการจัดให้มีบริการให้คำปรึกษาด้านสุขภาพจิต ปัญหาส่วนตัว และครอบครัว โดยมีช่องทางที่เข้าถึงง่าย เก็บความลับ และมีผู้เชี่ยวชาญให้คำปรึกษา | D20: • ระดับ 0: ไม่มีบริการให้คำปรึกษา • ระดับ 0.25: มีช่องทางให้คำปรึกษาเบื้องต้น แต่ยังไม่เป็นระบบ • ระดับ 0.50: มีระบบให้คำปรึกษา มีช่องทางที่ชัดเจน • ระดับ 0.75: มี EAP ที่ครบครัน มีผู้เชี่ยวชาญ มีการประชาสัมพันธ์ • ระดับ 1.0: มี EAP ครบวงจร มีการประเมินผลและพัฒนาอย่างต่อเนื่อง มีผลลัพธ์ที่ดี | G20: 1 | H20: =G20*20 -> 20 | I20: 1 | J20: =I20*20 -> 20
B21: H1.6: โครงการป้องกัน NCDs (Non-Communicable Diseases Prevention) | C21: สถานประกอบการมีโครงการป้องกันและควบคุมโรคไม่ติดต่อเรื้อรัง (NCDs) อย่างครอบคลุม เช่น เบาหวาน ความดันโลหิตสูง โรคหัวใจ มะเร็ง โดยมุ่งเน้นการลดพฤติกรรมเสี่ยง 4 ประการ (บุหรี่ เครื่องดื่มแอลกอฮอล์ อาหาร และการขาดการออกกำลังกาย) | D21: • ระดับ 0: ไม่มีการดำเนินงาน • ระดับ 0.25: มีการดำเนินงานเบื้องต้น แต่ยังไม่เป็นระบบ • ระดับ 0.50: มีการดำเนินงานที่เป็นระบบ มีหลักฐานประกอบ • ระดับ 0.75: มีการดำเนินงานครอบคลุม มีระบบติดตามและประเมินผล • ระดับ 1.0: มีการดำเนินงานครบถ้วนและมีประสิทธิภาพสูง มีผลลัพธ์ที่ดีและยั่งยืน | G21: 1 | H21: =G21*20 -> 20 | I21: 1 | J21: =I21*20 -> 20
B22: H1.7: การประเมินสุขภาพจิตและปัจจัยเสี่ยงทางจิตสังคม (Mental Health and Psychosocial Risk Assessment) | C22: สถานประกอบการมีการประเมินสุขภาพจิตและปัจจัยเสี่ยงทางจิตสังคมในการทำงาน เช่น ความเครียด ภาระงาน การคุกคาม การกลั่นแกล้ง อย่างสม่ำเสมอ และนำผลไปดำเนินการปรับปรุง | D22: • ระดับ 0: ไม่มีการดำเนินงาน • ระดับ 0.25: มีการดำเนินงานเบื้องต้น แต่ยังไม่เป็นระบบ • ระดับ 0.50: มีการดำเนินงานที่เป็นระบบ มีหลักฐานประกอบ • ระดับ 0.75: มีการดำเนินงานครอบคลุม มีระบบติดตามและประเมินผล • ระดับ 1.0: มีการดำเนินงานครบถ้วนและมีประสิทธิภาพสูง มีผลลัพธ์ที่ดีและยั่งยืน | G22: 1 | H22: =G22*20 -> 20 | I22: 1 | J22: =I22*20 -> 20
B23: H1.8: โครงการเลิกบุหรี่และแอลกอฮอล์ (Tobacco and Alcohol Cessation Program) | C23: สถานประกอบการมีนโยบายปลอดบุหรี่และควบคุมการดื่มแอลกอฮอล์ มีโครงการช่วยเหลือพนักงานเลิกบุหรี่และเครื่องดื่มแอลกอฮอล์ รวมถึงมาตรการป้องกันและลงโทษผู้ละเมิด | D23: • ระดับ 0: ไม่มีการดำเนินงาน • ระดับ 0.25: มีการดำเนินงานเบื้องต้น แต่ยังไม่เป็นระบบ • ระดับ 0.50: มีการดำเนินงานที่เป็นระบบ มีหลักฐานประกอบ • ระดับ 0.75: มีการดำเนินงานครอบคลุม มีระบบติดตามและประเมินผล • ระดับ 1.0: มีการดำเนินงานครบถ้วนและมีประสิทธิภาพสูง มีผลลัพธ์ที่ดีและยั่งยืน | G23: 1 | H23: =G23*20 -> 20 | I23: 1 | J23: =I23*20 -> 20
B24: H1.9: กิจกรรมส่งเสริมสุขภาพ 4 มิติ (Holistic Health Promotion Activities) | C24: สถานประกอบการจัดกิจกรรมส่งเสริมสุขภาพครอบคลุม 4 มิติ คือ กาย (ออกกำลังกาย โภชนาการ) จิต (จิตเวช สุขภาพจิต) สังคม (ความสัมพันธ์ Work-Life Balance) และจิตวิญญาณ (คุณธรรม จิตอาสา ศาสนา) | D24: • ระดับ 0: ไม่มีการดำเนินงาน • ระดับ 0.25: มีการดำเนินงานเบื้องต้น แต่ยังไม่เป็นระบบ • ระดับ 0.50: มีการดำเนินงานที่เป็นระบบ มีหลักฐานประกอบ • ระดับ 0.75: มีการดำเนินงานครอบคลุม มีระบบติดตามและประเมินผล • ระดับ 1.0: มีการดำเนินงานครบถ้วนและมีประสิทธิภาพสูง มีผลลัพธ์ที่ดีและยั่งยืน | G24: 0.5 | H24: =G24*20 -> 10 | I24: 1 | J24: =I24*20 -> 20
B25: H1.10: แกนนำสุขภาพองค์กร (Health Champions Network) | C25: สถานประกอบการแต่งตั้งและอบรมแกนนำสุขภาพ (Health Champions) อย่างน้อย 10 คนขึ้นไป หรือ 5% ของพนักงาน เพื่อเป็นผู้ขับเคลื่อนกิจกรรมสุขภาพและเป็นต้นแบบให้เพื่อนร่วมงาน | D25: • ระดับ 0: ไม่มีการดำเนินงาน • ระดับ 0.25: มีการดำเนินงานเบื้องต้น แต่ยังไม่เป็นระบบ • ระดับ 0.50: มีการดำเนินงานที่เป็นระบบ มีหลักฐานประกอบ • ระดับ 0.75: มีการดำเนินงานครอบคลุม มีระบบติดตามและประเมินผล • ระดับ 1.0: มีการดำเนินงานครบถ้วนและมีประสิทธิภาพสูง มีผลลัพธ์ที่ดีและยั่งยืน | G25: 1 | H25: =G25*20 -> 20 | I25: 1 | J25: =I25*20 -> 20
B26: H1.11: โภชนาการในที่ทำงาน (Nutrition at Workplace) | C26: สถานประกอบการจัดให้มีอาหารที่มีคุณค่าทางโภชนาการในโรงอาหารหรือร้านอาหาร มีการแสดงฉลากโภชนาการ และส่งเสริมพนักงานเลือกรับประทานอาหารสุขภาพ | D26: • ระดับ 0: ไม่มีการดำเนินงาน • ระดับ 0.25: มีการดำเนินงานเบื้องต้น แต่ยังไม่เป็นระบบ • ระดับ 0.50: มีการดำเนินงานที่เป็นระบบ มีหลักฐานประกอบ • ระดับ 0.75: มีการดำเนินงานครอบคลุม มีระบบติดตามและประเมินผล • ระดับ 1.0: มีการดำเนินงานครบถ้วนและมีประสิทธิภาพสูง มีผลลัพธ์ที่ดีและยั่งยืน | G26: 1 | H26: =G26*20 -> 20 | I26: 1 | J26: =I26*20 -> 20
B27: H1.12: การออกกำลังกายในองค์กร (Physical Activity Program) | C27: สถานประกอบการส่งเสริมให้พนักงานออกกำลังกายอย่างสม่ำเสมอ มีสถานที่และอุปกรณ์ออกกำลังกาย มีกิจกรรมกีฬาและนันทนาการ และมีระบบติดตามผล | D27: • ระดับ 0: ไม่มีการดำเนินงาน • ระดับ 0.25: มีการดำเนินงานเบื้องต้น แต่ยังไม่เป็นระบบ • ระดับ 0.50: มีการดำเนินงานที่เป็นระบบ มีหลักฐานประกอบ • ระดับ 0.75: มีการดำเนินงานครอบคลุม มีระบบติดตามและประเมินผล • ระดับ 1.0: มีการดำเนินงานครบถ้วนและมีประสิทธิภาพสูง มีผลลัพธ์ที่ดีและยั่งยืน | G27: 1 | H27: =G27*20 -> 20 | I27: 1 | J27: =I27*20 -> 20
B28: H1.13: สิทธิประโยชน์ด้านสุขภาพ (Health Benefits and Welfare) | C28: สถานประกอบการจัดสวัสดิการและสิทธิประโยชน์ด้านสุขภาพให้พนักงานอย่างครอบคลุม เช่น ประกันสุขภาพ ประกันอุบัติเหตุ ค่ารักษาพยาบาล และสวัสดิการอื่นๆ ที่เกี่ยวข้อง | D28: • ระดับ 0: ไม่มีการดำเนินงาน • ระดับ 0.25: มีการดำเนินงานเบื้องต้น แต่ยังไม่เป็นระบบ • ระดับ 0.50: มีการดำเนินงานที่เป็นระบบ มีหลักฐานประกอบ • ระดับ 0.75: มีการดำเนินงานครอบคลุม มีระบบติดตามและประเมินผล • ระดับ 1.0: มีการดำเนินงานครบถ้วนและมีประสิทธิภาพสูง มีผลลัพธ์ที่ดีและยั่งยืน | G28: 1 | H28: =G28*20 -> 20 | I28: 1 | J28: =I28*20 -> 20
... B30: H1.15: งานวิจัยและประเมินสุขภาวะองค์กร (Organizational Health Research) | C30: สถานประกอบการสนับสนุนการทำวิจัยหรือร่วมมือกับหน่วยงานวิชาการในการศึกษาวิจัยด้านสุขภาวะองค์กร เพื่อนำผลไปใช้ในการพัฒนาและปรับปรุงระบบอย่างต่อเนื่อง | D30: • ระดับ 0: ไม่มีการดำเนินงาน • ระดับ 0.25: มีการดำเนินงานเบื้องต้น แต่ยังไม่เป็นระบบ • ระดับ 0.50: มีการดำเนินงานที่เป็นระบบ มีหลักฐานประกอบ • ระดับ 0.75: มีการดำเนินงานครอบคลุม มีระบบติดตามและประเมินผล • ระดับ 1.0: มีการดำเนินงานครบถ้วนและมีประสิทธิภาพสูง มีผลลัพธ์ที่ดีและยั่งยืน | G30: 0.5 | H30: =G30*20 -> 10 | I30: 1 | J30: =I30*20 -> 20
D31: รวม คะแนน | G31: =SUM(G16:G30) -> 12.5 | H31: =SUM(H16:H30) -> 250 | I31: =SUM(I16:I30) -> 14.5 | J31: =SUM(J16:J30) -> 290

Sheet ทดสอบ
B1: ส่วนที่ 3: ตัวชี้วัดและเกณฑ์การประเมิน (60 ตัวชี้วัด)
B2: ส่วนนี้ประกอบด้วยรายละเอียดตัวชี้วัดทั้ง 60 ตัว แบ่งตามหมวดหมู่ 4 Pillars โดยแต่ละตัวชี้วัดจะมี:
B3: • คำอธิบายตัวชี้วัด (Indicator Definition)
B4: • เกณฑ์การประเมิน (Assessment Criteria) แบ่งเป็น 5 ระดับ (0, 0.25, 0.50, 0.75, 1.0)
B5: • หลักฐานประกอบ (Supporting Evidence)
B6: • การอ้างอิงหลักวิชาการและกฎหมาย (References)
B7: • ข้อเสนอแนะในการพัฒนา (Development Recommendations)
B9: Pillar 1: Health Promotion (H1) - การส่งเสริมสุขภาพ
B10: จำนวน 15 ตัวชี้วัด / น้ำหนักคะแนน 300 คะแนน
B12: H1.1: นโยบายสุขภาวะองค์กร (Organizational Health Policy)
B13: · คำอธิบายตัวชี้วัด:
B14: สถานประกอบการมีนโยบายสุขภาวะที่ชัดเจน เป็นลายลักษณ์อักษร ประกาศให้พนักงานทราบทั่วกัน และบูรณาการเข้ากับยุทธศาสตร์องค์กร มีการทบทวนปรับปรุงเป็นประจำทุกปี
B15: · เกณฑ์การประเมิน:
B16: ระดับ | C16: คำอธิบาย
B17: 0 | C17: ไม่มีนโยบายสุขภาวะเป็นลายลักษณ์อักษร
B18: 0.25 | C18: มีนโยบายสุขภาวะเป็นลายลักษณ์อักษร แต่ยังไม่ประกาศอย่างเป็นทางการ
B19: 0.5 | C19: มีนโยบายสุขภาวะที่ประกาศอย่างเป็นทางการ และแจ้งให้พนักงานทราบ
B20: 0.75 | C20: มีนโยบายสุขภาวะที่บูรณาการกับยุทธศาสตร์องค์กร มีการทบทวนเป็นประจำ
B21: 1 | C21: มีนโยบายสุขภาวะที่ครอบคลุม บูรณาการกับยุทธศาสตร์ มีการทบทวนและปรับปรุงต่อเนื่อง มีการวัดผลสัมฤทธิ์
B22: ผลการประเมิน | C22: 0.75
B23: · หลักฐานประกอบ: เอกสารนโยบาย, ประกาศนโยบาย, รายงานการประชุมผู้บริหาร, แผนยุทธศาสตร์, รายงานการทบทวนนโยบาย
C24: โปรดแนบ Link เอกสาร | D24: 1. เอกสารนโยบาย
B27: · การอ้างอิงหลักวิชาการ:
B28: เช่น WHO Healthy Workplace Framework (2010), Ottawa Charter for Health Promotion (1986), ISO 45001:2018 clause 5.2
C29: โปรดระบุอ้างอิง
B31: · ข้อเสนอแนะในการพัฒนา:
B32: เช่น | C32: • จัดทำนโยบายให้สอดคล้องกับบริบทองค์กร
C33: • ขอความเห็นชอบจากผู้บริหารระดับสูง
C34: • สื่อสารนโยบายผ่านช่องทางหลากหลาย
C35: • กำหนดตัวชี้วัดเพื่อติดตามผลการดำเนินงานตามนโยบาย
C36: โปรดระบุ
B38: H1.2: แผนปฏิบัติการสุขภาวะประจำปี (Annual Health Action Plan)
B39: · คำอธิบายตัวชี้วัด:
B40: สถานประกอบการมีแผนปฏิบัติการส่งเสริมสุขภาพประจำปีที่ชัดเจน มีกิจกรรมครอบคลุม มีงบประมาณและผู้รับผิดชอบที่ชัดเจน และมีการติดตามประเมินผล
B41: · เกณฑ์การประเมิน:
B42: ระดับ | C42: คำอธิบาย
B43: 0 | C43: ไม่มีแผนปฏิบัติการด้านสุขภาวะ
B44: 0.25 | C44: มีแผนปฏิบัติการเบื้องต้น แต่ยังไม่มีรายละเอียดครบถ้วน
B45: 0.5 | C45: มีแผนปฏิบัติการที่ชัดเจน มีงบประมาณและผู้รับผิดชอบ
B46: 0.75 | C46: มีแผนปฏิบัติการครอบคลุมทุกมิติของสุขภาวะ มีการติดตามผลเป็นระยะ
...

Sheet ส่วนที่ 3 (I)
A1: Pillar 2: Industrial Safety & Environment (I2)
A4: การประเมินผลการดำเนินการ (ประกอบด้วย จำนวน 15 ตัวชี้วัด / น้ำหนักคะแนน 300 คะแนน) | D4: กรอบแนวคิด : มุ่งเน้นการจัดการความปลอดภัยอาชีวอนามัยและสิ่งแวดล้อมในการทำงานตามมาตรฐานสากล ISO 45001:2018 (Occupational Health and Safety Management Systems), ISO 14001:2015 (Environmental Management Systems) และพระราชบัญญัติความปลอดภัย อาชีวอนามัย และสภาพแวดล้อมในการทำงาน พ.ศ. 2554
A7: สรุปผลคะแนน
A8: Industrial Safety & Environment (I2) - ความปลอดภัยและสิ่งแวดล้อม (คะแนนเต็ม = 300 คะแนน)
B9: คะแนนที่ได้ : | C9: =H30 -> 50
B10: ร้อยละ (%) : | C10: =(C9/I30)*100 -> 62.5
E13: การประเมินโดยตนเอง | J13: การประเมินโดยกรรมการ
A14: ตัวชี้วัด | B14: เกณฑ์ | C14: คำอธิบายตัวชี้วัด | D14: เกณฑ์การประเมิน | E14: ผลการดำเนินงาน | F14: หลักฐานประกอบ | G14: ระดับการประเมินตนเอง | H14: คะแนนที่ได้ | I14: คะแนนเต็ม | J14: ระดับการประเมินจากกรรมการ | K14: คะแนนที่ได้ | L14: คะแนนเต็ม | M14: ข้อเสนอแนะในการพัฒนา
A15: Pillar 2: Industrial Safety & Environment (I2) - ความปลอดภัยและสิ่งแวดล้อม | B15: I2.1: นโยบายความปลอดภัยและสิ่งแวดล้อม (OHS & Environment Policy) | C15: สถานประกอบการมีระบบและการดำเนินงานด้านนโยบายความปลอดภัยและสิ่งแวดล้อมตามมาตรฐานและกฎหมายที่เกี่ยวข้อง | D15: • ระดับ 0: ไม่มีระบบหรือการดำเนินงาน • ระดับ 0.25: มีระบบเบื้องต้น แต่ยังไม่ครบถ้วนตามกฎหมาย • ระดับ 0.50: มีระบบและปฏิบัติตามกฎหมายขั้นพื้นฐาน • ระดับ 0.75: มีระบบครบถ้วน มีการติดตามและปรับปรุงสม่ำเสมอ • ระดับ 1.0: มีระบบที่เป็นเลิศ เป็นไปตามมาตรฐานสากล มีการพัฒนาต่อเนื่อง • N/A: ไม่รับการประเมิน | G15: N/A | H15: =if(G15=0,(0*20),if(G15=0.25,(0.25*20),if(G15=0.5,(0.5*20),if(G15=0.75,(0.75*20),if(G15=1,(1*20),"NA"))))) -> NA | I15: =if(ISNUMBER(H15),20,H15) -> NA | J15: N/A | K15: =if(J15=0,(0*20),if(J15=0.25,(0.25*20),if(J15=0.5,(0.5*20),if(J15=0.75,(0.75*20),if(J15=1,(1*20),"NA"))))) -> NA | L15: =if(ISNUMBER(K15),20,K15) -> NA
B16: I2.2: ระบบ HIRARC (Hazard Identification & Risk Assessment) | C16: สถานประกอบการมีระบบและการดำเนินงานด้านระบบ HIRARCตามมาตรฐานและกฎหมายที่เกี่ยวข้อง | D16: • ระดับ 0: ไม่มีระบบหรือการดำเนินงาน • ระดับ 0.25: มีระบบเบื้องต้น แต่ยังไม่ครบถ้วนตามกฎหมาย • ระดับ 0.50: มีระบบและปฏิบัติตามกฎหมายขั้นพื้นฐาน • ระดับ 0.75: มีระบบครบถ้วน มีการติดตามและปรับปรุงสม่ำเสมอ • ระดับ 1.0: มีระบบที่เป็นเลิศ เป็นไปตามมาตรฐานสากล มีการพัฒนาต่อเนื่อง • N/A: ไม่รับการประเมิน | G16: 1 | H16: =if(G16=0,(0*20),if(G16=0.25,(0.25*20),if(G16=0.5,(0.5*20),if(G16=0.75,(0.75*20),if(G16=1,(1*20),"NA"))))) -> 20 | I16: =if(ISNUMBER(H16),20,H16) -> 20 | J16: 0.75 | K16: =if(J16=0,(0*20),if(J16=0.25,(0.25*20),if(J16=0.5,(0.5*20),if(J16=0.75,(0.75*20),if(J16=1,(1*20),"NA"))))) -> 15 | L16: =if(ISNUMBER(K16),20,K16) -> 20
B17: I2.3: การป้องกันและรายงานอุบัติเหตุ (Accident Prevention & Reporting) | C17: สถานประกอบการมีระบบและการดำเนินงานด้านการป้องกันและรายงานอุบัติเหตุตามมาตรฐานและกฎหมายที่เกี่ยวข้อง | D17: • ระดับ 0: ไม่มีระบบหรือการดำเนินงาน • ระดับ 0.25: มีระบบเบื้องต้น แต่ยังไม่ครบถ้วนตามกฎหมาย • ระดับ 0.50: มีระบบและปฏิบัติตามกฎหมายขั้นพื้นฐาน • ระดับ 0.75: มีระบบครบถ้วน มีการติดตามและปรับปรุงสม่ำเสมอ • ระดับ 1.0: มีระบบที่เป็นเลิศ เป็นไปตามมาตรฐานสากล มีการพัฒนาต่อเนื่อง | G17: N/A | H17: =if(G17=0,(0*20),if(G17=0.25,(0.25*20),if(G17=0.5,(0.5*20),if(G17=0.75,(0.75*20),if(G17=1,(1*20),"NA"))))) -> NA | I17: =if(ISNUMBER(H17),20,H17) -> NA | J17: 0.5 | K17: =if(J17=0,(0*20),if(J17=0.25,(0.25*20),if(J17=0.5,(0.5*20),if(J17=0.75,(0.75*20),if(J17=1,(1*20),"NA"))))) -> 10 | L17: =if(ISNUMBER(K17),20,K17) -> 20
B18: I2.4: อุปกรณ์ป้องกันอันตรายส่วนบุคคล (PPE) (Personal Protective Equipment) | C18: สถานประกอบการมีระบบและการดำเนินงานด้านอุปกรณ์ป้องกันอันตรายส่วนบุคคล (PPE)ตามมาตรฐานและกฎหมายที่เกี่ยวข้อง | D18: • ระดับ 0: ไม่มีระบบหรือการดำเนินงาน • ระดับ 0.25: มีระบบเบื้องต้น แต่ยังไม่ครบถ้วนตามกฎหมาย • ระดับ 0.50: มีระบบและปฏิบัติตามกฎหมายขั้นพื้นฐาน • ระดับ 0.75: มีระบบครบถ้วน มีการติดตามและปรับปรุงสม่ำเสมอ • ระดับ 1.0: มีระบบที่เป็นเลิศ เป็นไปตามมาตรฐานสากล มีการพัฒนาต่อเนื่อง | G18: N/A | H18: =if(G18=0,(0*20),if(G18=0.25,(0.25*20),if(G18=0.5,(0.5*20),if(G18=0.75,(0.75*20),if(G18=1,(1*20),"NA"))))) -> NA | I18: =if(ISNUMBER(H18),20,H18) -> NA | J18: N/A | K18: =if(J18=0,(0*20),if(J18=0.25,(0.25*20),if(J18=0.5,(0.5*20),if(J18=0.75,(0.75*20),if(J18=1,(1*20),"NA"))))) -> NA | L18: =if(ISNUMBER(K18),20,K18) -> NA
B19: I2.5: การตรวจวัดสภาพแวดล้อมการทำงาน (Workplace Environment Monitoring) | C19: สถานประกอบการมีระบบและการดำเนินงานด้านการตรวจวัดสภาพแวดล้อมการทำงานตามมาตรฐานและกฎหมายที่เกี่ยวข้อง | D19: • ระดับ 0: ไม่มีระบบหรือการดำเนินงาน • ระดับ 0.25: มีระบบเบื้องต้น แต่ยังไม่ครบถ้วนตามกฎหมาย • ระดับ 0.50: มีระบบและปฏิบัติตามกฎหมายขั้นพื้นฐาน • ระดับ 0.75: มีระบบครบถ้วน มีการติดตามและปรับปรุงสม่ำเสมอ • ระดับ 1.0: มีระบบที่เป็นเลิศ เป็นไปตามมาตรฐานสากล มีการพัฒนาต่อเนื่อง | G19: N/A | H19: =if(G19=0,(0*20),if(G19=0.25,(0.25*20),if(G19=0.5,(0.5*20),if(G19=0.75,(0.75*20),if(G19=1,(1*20),"NA"))))) -> NA | I19: =if(ISNUMBER(H19),20,H19) -> NA | J19: N/A | K19: =if(J19=0,(0*20),if(J19=0.25,(0.25*20),if(J19=0.5,(0.5*20),if(J19=0.75,(0.75*20),if(J19=1,(1*20),"NA"))))) -> NA | L19: =if(ISNUMBER(K19),20,K19) -> NA
B20: I2.6: ระบบบริหารจัดการสารเคมี (Chemical Management System) | C20: สถานประกอบการมีระบบและการดำเนินงานด้านระบบบริหารจัดการสารเคมีตามมาตรฐานและกฎหมายที่เกี่ยวข้อง | D20: • ระดับ 0: ไม่มีระบบหรือการดำเนินงาน • ระดับ 0.25: มีระบบเบื้องต้น แต่ยังไม่ครบถ้วนตามกฎหมาย • ระดับ 0.50: มีระบบและปฏิบัติตามกฎหมายขั้นพื้นฐาน • ระดับ 0.75: มีระบบครบถ้วน มีการติดตามและปรับปรุงสม่ำเสมอ • ระดับ 1.0: มีระบบที่เป็นเลิศ เป็นไปตามมาตรฐานสากล มีการพัฒนาต่อเนื่อง | G20: 0.5 | H20: =if(G20=0,(0*20),if(G20=0.25,(0.25*20),if(G20=0.5,(0.5*20),if(G20=0.75,(0.75*20),if(G20=1,(1*20),"NA"))))) -> 10 | I20: =if(ISNUMBER(H20),20,H20) -> 20 | J20: N/A | K20: =if(J20=0,(0*20),if(J20=0.25,(0.25*20),if(J20=0.5,(0.5*20),if(J20=0.75,(0.75*20),if(J20=1,(1*20),"NA"))))) -> NA | L20: =if(ISNUMBER(K20),20,K20) -> NA
B21: I2.7: การป้องกันและระงับอัคคีภัย (Fire Prevention & Control) | C21: สถานประกอบการมีระบบและการดำเนินงานด้านการป้องกันและระงับอัคคีภัยตามมาตรฐานและกฎหมายที่เกี่ยวข้อง | D21: • ระดับ 0: ไม่มีระบบหรือการดำเนินงาน • ระดับ 0.25: มีระบบเบื้องต้น แต่ยังไม่ครบถ้วนตามกฎหมาย • ระดับ 0.50: มีระบบและปฏิบัติตามกฎหมายขั้นพื้นฐาน • ระดับ 0.75: มีระบบครบถ้วน มีการติดตามและปรับปรุงสม่ำเสมอ • ระดับ 1.0: มีระบบที่เป็นเลิศ เป็นไปตามมาตรฐานสากล มีการพัฒนาต่อเนื่อง | G21: 0.75 | H21: =if(G21=0,(0*20),if(G21=0.25,(0.25*20),if(G21=0.5,(0.5*20),if(G21=0.75,(0.75*20),if(G21=1,(1*20),"NA"))))) -> 15 | I21: =if(ISNUMBER(H21),20,H21) -> 20 | J21: N/A | K21: =if(J21=0,(0*20),if(J21=0.25,(0.25*20),if(J21=0.5,(0.5*20),if(J21=0.75,(0.75*20),if(J21=1,(1*20),"NA"))))) -> NA | L21: =if(ISNUMBER(K21),20,K21) -> NA
B22: I2.8: แผนฉุกเฉินและการซ้อมหนีไฟ (Emergency Response Plan) | C22: สถานประกอบการมีระบบและการดำเนินงานด้านแผนฉุกเฉินและการซ้อมหนีไฟตามมาตรฐานและกฎหมายที่เกี่ยวข้อง | D22: • ระดับ 0: ไม่มีระบบหรือการดำเนินงาน • ระดับ 0.25: มีระบบเบื้องต้น แต่ยังไม่ครบถ้วนตามกฎหมาย • ระดับ 0.50: มีระบบและปฏิบัติตามกฎหมายขั้นพื้นฐาน • ระดับ 0.75: มีระบบครบถ้วน มีการติดตามและปรับปรุงสม่ำเสมอ • ระดับ 1.0: มีระบบที่เป็นเลิศ เป็นไปตามมาตรฐานสากล มีการพัฒนาต่อเนื่อง | G22: 0.25 | H22: =if(G22=0,(0*20),if(G22=0.25,(0.25*20),if(G22=0.5,(0.5*20),if(G22=0.75,(0.75*20),if(G22=1,(1*20),"NA"))))) -> 5 | I22: =if(ISNUMBER(H22),20,H22) -> 20 | J22: N/A | K22: =if(J22=0,(0*20),if(J22=0.25,(0.25*20),if(J22=0.5,(0.5*20),if(J22=0.75,(0.75*20),if(J22=1,(1*20),"NA"))))) -> NA | L22: =if(ISNUMBER(K22),20,K22) -> NA
B23: I2.9: ความปลอดภัยเครื่องจักรและอุปกรณ์ (Machine & Equipment Safety) | C23: สถานประกอบการมีระบบและการดำเนินงานด้านความปลอดภัยเครื่องจักรและอุปกรณ์ตามมาตรฐานและกฎหมายที่เกี่ยวข้อง | D23: • ระดับ 0: ไม่มีระบบหรือการดำเนินงาน • ระดับ 0.25: มีระบบเบื้องต้น แต่ยังไม่ครบถ้วนตามกฎหมาย • ระดับ 0.50: มีระบบและปฏิบัติตามกฎหมายขั้นพื้นฐาน • ระดับ 0.75: มีระบบครบถ้วน มีการติดตามและปรับปรุงสม่ำเสมอ • ระดับ 1.0: มีระบบที่เป็นเลิศ เป็นไปตามมาตรฐานสากล มีการพัฒนาต่อเนื่อง | G23: N/A | H23: =if(G23=0,(0*20),if(G23=0.25,(0.25*20),if(G23=0.5,(0.5*20),if(G23=0.75,(0.75*20),if(G23=1,(1*20),"NA"))))) -> NA | I23: =if(ISNUMBER(H23),20,H23) -> NA | J23: N/A | K23: =if(J23=0,(0*20),if(J23=0.25,(0.25*20),if(J23=0.5,(0.5*20),if(J23=0.75,(0.75*20),if(J23=1,(1*20),"NA"))))) -> NA | L23: =if(ISNUMBER(K23),20,K23) -> NA
B24: I2.10: การจัดการคุณภาพอากาศและเสียง (Air Quality & Noise Management) | C24: สถานประกอบการมีระบบและการดำเนินงานด้านการจัดการคุณภาพอากาศและเสียงตามมาตรฐานและกฎหมายที่เกี่ยวข้อง | D24: • ระดับ 0: ไม่มีระบบหรือการดำเนินงาน • ระดับ 0.25: มีระบบเบื้องต้น แต่ยังไม่ครบถ้วนตามกฎหมาย • ระดับ 0.50: มีระบบและปฏิบัติตามกฎหมายขั้นพื้นฐาน • ระดับ 0.75: มีระบบครบถ้วน มีการติดตามและปรับปรุงสม่ำเสมอ • ระดับ 1.0: มีระบบที่เป็นเลิศ เป็นไปตามมาตรฐานสากล มีการพัฒนาต่อเนื่อง | G24: N/A | H24: =if(G24=0,(0*20),if(G24=0.25,(0.25*20),if(G24=0.5,(0.5*20),if(G24=0.75,(0.75*20),if(G24=1,(1*20),"NA"))))) -> NA | I24: =if(ISNUMBER(H24),20,H24) -> NA | J24: N/A | K24: =if(J24=0,(0*20),if(J24=0.25,(0.25*20),if(J24=0.5,(0.5*20),if(J24=0.75,(0.75*20),if(J24=1,(1*20),"NA"))))) -> NA | L24: =if(ISNUMBER(K24),20,K24) -> NA
B25: I2.11: การจัดการน้ำเสียและของเสีย (Wastewater & Waste Management) | C25: สถานประกอบการมีระบบและการดำเนินงานด้านการจัดการน้ำเสียและของเสียตามมาตรฐานและกฎหมายที่เกี่ยวข้อง | D25: • ระดับ 0: ไม่มีระบบหรือการดำเนินงาน • ระดับ 0.25: มีระบบเบื้องต้น แต่ยังไม่ครบถ้วนตามกฎหมาย • ระดับ 0.50: มีระบบและปฏิบัติตามกฎหมายขั้นพื้นฐาน • ระดับ 0.75: มีระบบครบถ้วน มีการติดตามและปรับปรุงสม่ำเสมอ • ระดับ 1.0: มีระบบที่เป็นเลิศ เป็นไปตามมาตรฐานสากล มีการพัฒนาต่อเนื่อง | G25: N/A | H25: =if(G25=0,(0*20),if(G25=0.25,(0.25*20),if(G25=0.5,(0.5*20),if(G25=0.75,(0.75*20),if(G25=1,(1*20),"NA"))))) -> NA | I25: =if(ISNUMBER(H25),20,H25) -> NA | J25: N/A | K25: =if(J25=0,(0*20),if(J25=0.25,(0.25*20),if(J25=0.5,(0.5*20),if(J25=0.75,(0.75*20),if(J25=1,(1*20),"NA"))))) -> NA | L25: =if(ISNUMBER(K25),20,K25) -> NA
B26: I2.12: การประหยัดพลังงาน (Energy Conservation) | C26: สถานประกอบการมีระบบและการดำเนินงานด้านการประหยัดพลังงานตามมาตรฐานและกฎหมายที่เกี่ยวข้อง | D26: • ระดับ 0: ไม่มีระบบหรือการดำเนินงาน • ระดับ 0.25: มีระบบเบื้องต้น แต่ยังไม่ครบถ้วนตามกฎหมาย • ระดับ 0.50: มีระบบและปฏิบัติตามกฎหมายขั้นพื้นฐาน • ระดับ 0.75: มีระบบครบถ้วน มีการติดตามและปรับปรุงสม่ำเสมอ • ระดับ 1.0: มีระบบที่เป็นเลิศ เป็นไปตามมาตรฐานสากล มีการพัฒนาต่อเนื่อง | G26: N/A | H26: =if(G26=0,(0*20),if(G26=0.25,(0.25*20),if(G26=0.5,(0.5*20),if(G26=0.75,(0.75*20),if(G26=1,(1*20),"NA"))))) -> NA | I26: =if(ISNUMBER(H26),20,H26) -> NA | J26: N/A | K26: =if(J26=0,(0*20),if(J26=0.25,(0.25*20),if(J26=0.5,(0.5*20),if(J26=0.75,(0.75*20),if(J26=1,(1*20),"NA"))))) -> NA | L26: =if(ISNUMBER(K26),20,K26) -> NA
B27: I2.13: การจัดการก๊าซเรือนกระจก (GHG Management) | C27: สถานประกอบการมีระบบและการดำเนินงานด้านการจัดการก๊าซเรือนกระจกตามมาตรฐานและกฎหมายที่เกี่ยวข้อง | D27: • ระดับ 0: ไม่มีระบบหรือการดำเนินงาน • ระดับ 0.25: มีระบบเบื้องต้น แต่ยังไม่ครบถ้วนตามกฎหมาย • ระดับ 0.50: มีระบบและปฏิบัติตามกฎหมายขั้นพื้นฐาน • ระดับ 0.75: มีระบบครบถ้วน มีการติดตามและปรับปรุงสม่ำเสมอ • ระดับ 1.0: มีระบบที่เป็นเลิศ เป็นไปตามมาตรฐานสากล มีการพัฒนาต่อเนื่อง | G27: N/A | H27: =if(G27=0,(0*20),if(G27=0.25,(0.25*20),if(G27=0.5,(0.5*20),if(G27=0.75,(0.75*20),if(G27=1,(1*20),"NA"))))) -> NA | I27: =if(ISNUMBER(H27),20,H27) -> NA | J27: N/A | K27: =if(J27=0,(0*20),if(J27=0.25,(0.25*20),if(J27=0.5,(0.5*20),if(J27=0.75,(0.75*20),if(J27=1,(1*20),"NA"))))) -> NA | L27: =if(ISNUMBER(K27),20,K27) -> NA
B28: I2.14: ระบบ ISO หรือมาตรฐานสากล (ISO Certification) | C28: สถานประกอบการมีระบบและการดำเนินงานด้านระบบ ISO หรือมาตรฐานสากลตามมาตรฐานและกฎหมายที่เกี่ยวข้อง | D28: • ระดับ 0: ไม่มีระบบหรือการดำเนินงาน • ระดับ 0.25: มีระบบเบื้องต้น แต่ยังไม่ครบถ้วนตามกฎหมาย • ระดับ 0.50: มีระบบและปฏิบัติตามกฎหมายขั้นพื้นฐาน • ระดับ 0.75: มีระบบครบถ้วน มีการติดตามและปรับปรุงสม่ำเสมอ • ระดับ 1.0: มีระบบที่เป็นเลิศ เป็นไปตามมาตรฐานสากล มีการพัฒนาต่อเนื่อง | G28: N/A | H28: =if(G28=0,(0*20),if(G28=0.25,(0.25*20),if(G28=0.5,(0.5*20),if(G28=0.75,(0.75*20),if(G28=1,(1*20),"NA"))))) -> NA | I28: =if(ISNUMBER(H28),20,H28) -> NA | J28: N/A | K28: =if(J28=0,(0*20),if(J28=0.25,(0.25*20),if(J28=0.5,(0.5*20),if(J28=0.75,(0.75*20),if(J28=1,(1*20),"NA"))))) -> NA | L28: =if(ISNUMBER(K28),20,K28) -> NA
B29: I2.15: การตรวจ Audit ด้านความปลอดภัยและสิ่งแวดล้อม (Safety & Environment Audit) | C29: สถานประกอบการมีระบบและการดำเนินงานด้านการตรวจ Audit ด้านความปลอดภัยและสิ่งแวดล้อมตามมาตรฐานและกฎหมายที่เกี่ยวข้อง | D29: • ระดับ 0: ไม่มีระบบหรือการดำเนินงาน • ระดับ 0.25: มีระบบเบื้องต้น แต่ยังไม่ครบถ้วนตามกฎหมาย • ระดับ 0.50: มีระบบและปฏิบัติตามกฎหมายขั้นพื้นฐาน • ระดับ 0.75: มีระบบครบถ้วน มีการติดตามและปรับปรุงสม่ำเสมอ • ระดับ 1.0: มีระบบที่เป็นเลิศ เป็นไปตามมาตรฐานสากล มีการพัฒนาต่อเนื่อง | G29: N/A | H29: =if(G29=0,(0*20),if(G29=0.25,(0.25*20),if(G29=0.5,(0.5*20),if(G29=0.75,(0.75*20),if(G29=1,(1*20),"NA"))))) -> NA | I29: =if(ISNUMBER(H29),20,H29) -> NA | J29: 0.75 | K29: =if(J29=0,(0*20),if(J29=0.25,(0.25*20),if(J29=0.5,(0.5*20),if(J29=0.75,(0.75*20),if(J29=1,(1*20),"NA"))))) -> 15 | L29: =if(ISNUMBER(K29),20,K29) -> 20
D30: รวม คะแนน | G30: =SUM(G15:G29) -> 2.5 | H30: =SUMif(H15:H29,"<>N/A") -> 50 | I30: =SUMif(I15:I29,"<>N/A") -> 80 | J30: =SUM(J15:J29) -> 2 | K30: =SUMif(K15:K29,"<>N/A") -> 40 | L30: =SUMif(L15:L29,"<>N/A") -> 60

Sheet ส่วนที่ 3 (C)
A1: Pillar 3: Community Engagement (C3)
A4: การประเมินผลการดำเนินการ (ประกอบด้วย จำนวน 15 ตัวชี้วัด / น้ำหนักคะแนน 200 คะแนน) | D4: กรอบแนวคิด : มุ่งเน้นการสร้างความสัมพันธ์เชิงบวกระหว่างสถานประกอบการกับชุมชนโดยรอบ ตามแนวคิด Shared Value Creation และ Social License to Operate เชื่อมโยงกับเป้าหมายการพัฒนาที่ยั่งยืน (SDGs) โดยเฉพาะเป้าหมายที่ 3 (สุขภาพและความเป็นอยู่ที่ดี), เป้าหมายที่ 11 (เมืองและชุมชนที่ยั่งยืน) และเป้าหมายที่ 17 (ความร่วมมือเพื่อการพัฒนา)
A7: สรุปผลคะแนน
A8: Community Engagement (C3) - การมีส่วนร่วมกับชุมชน (คะแนนเต็ม = 200 คะแนน)
B9: คะแนนที่ได้ : | C9: =H30 -> 200
B10: ร้อยละ (%) : | C10: =(C9/200)*100 -> 100
E13: การประเมินโดยตนเอง | I13: การประเมินโดยกรรมการ
A14: ตัวชี้วัด | B14: เกณฑ์ | C14: คำอธิบายตัวชี้วัด | D14: เกณฑ์การประเมิน | E14: ผลการดำเนินงาน | F14: หลักฐานประกอบ | G14: ระดับการประเมินตนเอง | H14: คะแนนที่ได้ | I14: ระดับการประเมินจากกรรมการ | J14: คะแนนที่ได้ | K14: ข้อเสนอแนะในการพัฒนา
A15: Pillar 3: Community Engagement (C3) - การมีส่วนร่วมกับชุมชน | B15: C3.1: นโยบาย CSR และชุมชนสัมพันธ์ (CSR & Community Relations Policy) | C15: สถานประกอบการมีการดำเนินงานด้านนโยบาย CSR และชุมชนสัมพันธ์อย่างต่อเนื่องและสร้างผลกระทบเชิงบวกต่อชุมชน | D15: • ระดับ 0: ไม่มีการดำเนินงาน • ระดับ 0.25: มีการดำเนินงานเบื้องต้น เป็นครั้งคราว • ระดับ 0.50: มีโครงการและกิจกรรมสม่ำเสมอ • ระดับ 0.75: มีโครงการที่ครอบคลุม มีการติดตามและประเมินผล • ระดับ 1.0: มีโครงการที่ยั่งยืน สร้างคุณค่าร่วมกับชุมชน มีผลลัพธ์ที่วัดได้ | G15: 1 | H15: =G15*(200/15) -> 13.333333 | I15: 1 | J15: =I15*(200/15) -> 13.333333
B16: C3.2: การมีส่วนร่วมของชุมชน (Community Participation) | C16: สถานประกอบการมีการดำเนินงานด้านการมีส่วนร่วมของชุมชนอย่างต่อเนื่องและสร้างผลกระทบเชิงบวกต่อชุมชน | D16: • ระดับ 0: ไม่มีการดำเนินงาน • ระดับ 0.25: มีการดำเนินงานเบื้องต้น เป็นครั้งคราว • ระดับ 0.50: มีโครงการและกิจกรรมสม่ำเสมอ • ระดับ 0.75: มีโครงการที่ครอบคลุม มีการติดตามและประเมินผล • ระดับ 1.0: มีโครงการที่ยั่งยืน สร้างคุณค่าร่วมกับชุมชน มีผลลัพธ์ที่วัดได้ | G16: 1 | H16: =G16*(200/15) -> 13.333333 | I16: 1 | J16: =I16*(200/15) -> 13.333333
B17: C3.3: ช่องทางรับฟังความคิดเห็นและข้อร้องเรียน (Feedback & Complaint Channels) | C17: สถานประกอบการมีการดำเนินงานด้านช่องทางรับฟังความคิดเห็นและข้อร้องเรียนอย่างต่อเนื่องและสร้างผลกระทบเชิงบวกต่อชุมชน | D17: • ระดับ 0: ไม่มีการดำเนินงาน • ระดับ 0.25: มีการดำเนินงานเบื้องต้น เป็นครั้งคราว • ระดับ 0.50: มีโครงการและกิจกรรมสม่ำเสมอ • ระดับ 0.75: มีโครงการที่ครอบคลุม มีการติดตามและประเมินผล • ระดับ 1.0: มีโครงการที่ยั่งยืน สร้างคุณค่าร่วมกับชุมชน มีผลลัพธ์ที่วัดได้ | G17: 1 | H17: =G17*(200/15) -> 13.333333 | I17: 1 | J17: =I17*(200/15) -> 13.333333
B18: C3.4: โครงการส่งเสริมสุขภาพชุมชน (Community Health Promotion) | C18: สถานประกอบการมีการดำเนินงานด้านโครงการส่งเสริมสุขภาพชุมชนอย่างต่อเนื่องและสร้างผลกระทบเชิงบวกต่อชุมชน | D18: • ระดับ 0: ไม่มีการดำเนินงาน • ระดับ 0.25: มีการดำเนินงานเบื้องต้น เป็นครั้งคราว • ระดับ 0.50: มีโครงการและกิจกรรมสม่ำเสมอ • ระดับ 0.75: มีโครงการที่ครอบคลุม มีการติดตามและประเมินผล • ระดับ 1.0: มีโครงการที่ยั่งยืน สร้างคุณค่าร่วมกับชุมชน มีผลลัพธ์ที่วัดได้ | G18: 1 | H18: =G18*(200/15) -> 13.333333 | I18: 1 | J18: =I18*(200/15) -> 13.333333
B19: C3.5: โครงการพัฒนาคุณภาพชีวิตชุมชน (Community Quality of Life) | C19: สถานประกอบการมีการดำเนินงานด้านโครงการพัฒนาคุณภาพชีวิตชุมชนอย่างต่อเนื่องและสร้างผลกระทบเชิงบวกต่อชุมชน | D19: • ระดับ 0: ไม่มีการดำเนินงาน • ระดับ 0.25: มีการดำเนินงานเบื้องต้น เป็นครั้งคราว • ระดับ 0.50: มีโครงการและกิจกรรมสม่ำเสมอ • ระดับ 0.75: มีโครงการที่ครอบคลุม มีการติดตามและประเมินผล • ระดับ 1.0: มีโครงการที่ยั่งยืน สร้างคุณค่าร่วมกับชุมชน มีผลลัพธ์ที่วัดได้ | G19: 1 | H19: =G19*(200/15) -> 13.333333 | I19: 1 | J19: =I19*(200/15) -> 13.333333
B20: C3.6: การสนับสนุนการศึกษาและทุนการศึกษา (Education Support) | C20: สถานประกอบการมีการดำเนินงานด้านการสนับสนุนการศึกษาและทุนการศึกษาอย่างต่อเนื่องและสร้างผลกระทบเชิงบวกต่อชุมชน | D20: • ระดับ 0: ไม่มีการดำเนินงาน • ระดับ 0.25: มีการดำเนินงานเบื้องต้น เป็นครั้งคราว • ระดับ 0.50: มีโครงการและกิจกรรมสม่ำเสมอ • ระดับ 0.75: มีโครงการที่ครอบคลุม มีการติดตามและประเมินผล • ระดับ 1.0: มีโครงการที่ยั่งยืน สร้างคุณค่าร่วมกับชุมชน มีผลลัพธ์ที่วัดได้ | G20: 1 | H20: =G20*(200/15) -> 13.333333 | I20: 1 | J20: =I20*(200/15) -> 13.333333
B21: C3.7: การส่งเสริมอาชีพและรายได้ชุมชน (Occupation & Income Generation) | C21: สถานประกอบการมีการดำเนินงานด้านการส่งเสริมอาชีพและรายได้ชุมชนอย่างต่อเนื่องและสร้างผลกระทบเชิงบวกต่อชุมชน | D21: • ระดับ 0: ไม่มีการดำเนินงาน • ระดับ 0.25: มีการดำเนินงานเบื้องต้น เป็นครั้งคราว • ระดับ 0.50: มีโครงการและกิจกรรมสม่ำเสมอ • ระดับ 0.75: มีโครงการที่ครอบคลุม มีการติดตามและประเมินผล • ระดับ 1.0: มีโครงการที่ยั่งยืน สร้างคุณค่าร่วมกับชุมชน มีผลลัพธ์ที่วัดได้ | G21: 1 | H21: =G21*(200/15) -> 13.333333 | I21: 1 | J21: =I21*(200/15) -> 13.333333
B22: C3.8: การดูแลสิ่งแวดล้อมชุมชน (Community Environment Care) | C22: สถานประกอบการมีการดำเนินงานด้านการดูแลสิ่งแวดล้อมชุมชนอย่างต่อเนื่องและสร้างผลกระทบเชิงบวกต่อชุมชน | D22: • ระดับ 0: ไม่มีการดำเนินงาน • ระดับ 0.25: มีการดำเนินงานเบื้องต้น เป็นครั้งคราว • ระดับ 0.50: มีโครงการและกิจกรรมสม่ำเสมอ • ระดับ 0.75: มีโครงการที่ครอบคลุม มีการติดตามและประเมินผล • ระดับ 1.0: มีโครงการที่ยั่งยืน สร้างคุณค่าร่วมกับชุมชน มีผลลัพธ์ที่วัดได้ | G22: 1 | H22: =G22*(200/15) -> 13.333333 | I22: 1 | J22: =I22*(200/15) -> 13.333333
B23: C3.9: การจัดการผลกระทบต่อชุมชน (Community Impact Management) | C23: สถานประกอบการมีการดำเนินงานด้านการจัดการผลกระทบต่อชุมชนอย่างต่อเนื่องและสร้างผลกระทบเชิงบวกต่อชุมชน | D23: • ระดับ 0: ไม่มีการดำเนินงาน • ระดับ 0.25: มีการดำเนินงานเบื้องต้น เป็นครั้งคราว • ระดับ 0.50: มีโครงการและกิจกรรมสม่ำเสมอ • ระดับ 0.75: มีโครงการที่ครอบคลุม มีการติดตามและประเมินผล • ระดับ 1.0: มีโครงการที่ยั่งยืน สร้างคุณค่าร่วมกับชุมชน มีผลลัพธ์ที่วัดได้ | G23: 1 | H23: =G23*(200/15) -> 13.333333 | I23: 1 | J23: =I23*(200/15) -> 13.333333
B24: C3.10: การสนับสนุนโครงสร้างพื้นฐานชุมชน (Community Infrastructure Support) | C24: สถานประกอบการมีการดำเนินงานด้านการสนับสนุนโครงสร้างพื้นฐานชุมชนอย่างต่อเนื่องและสร้างผลกระทบเชิงบวกต่อชุมชน | D24: • ระดับ 0: ไม่มีการดำเนินงาน • ระดับ 0.25: มีการดำเนินงานเบื้องต้น เป็นครั้งคราว • ระดับ 0.50: มีโครงการและกิจกรรมสม่ำเสมอ • ระดับ 0.75: มีโครงการที่ครอบคลุม มีการติดตามและประเมินผล • ระดับ 1.0: มีโครงการที่ยั่งยืน สร้างคุณค่าร่วมกับชุมชน มีผลลัพธ์ที่วัดได้ | G24: 1 | H24: =G24*(200/15) -> 13.333333 | I24: 1 | J24: =I24*(200/15) -> 13.333333
B25: C3.11: การส่งเสริมวัฒนธรรมและประเพณีท้องถิ่น (Local Culture Promotion) | C25: สถานประกอบการมีการดำเนินงานด้านการส่งเสริมวัฒนธรรมและประเพณีท้องถิ่นอย่างต่อเนื่องและสร้างผลกระทบเชิงบวกต่อชุมชน | D25: • ระดับ 0: ไม่มีการดำเนินงาน • ระดับ 0.25: มีการดำเนินงานเบื้องต้น เป็นครั้งคราว • ระดับ 0.50: มีโครงการและกิจกรรมสม่ำเสมอ • ระดับ 0.75: มีโครงการที่ครอบคลุม มีการติดตามและประเมินผล • ระดับ 1.0: มีโครงการที่ยั่งยืน สร้างคุณค่าร่วมกับชุมชน มีผลลัพธ์ที่วัดได้ | G25: 1 | H25: =G25*(200/15) -> 13.333333 | I25: 1 | J25: =I25*(200/15) -> 13.333333
B26: C3.12: การประสานงานกับหน่วยงานท้องถิ่น (Local Authority Coordination) | C26: สถานประกอบการมีการดำเนินงานด้านการประสานงานกับหน่วยงานท้องถิ่นอย่างต่อเนื่องและสร้างผลกระทบเชิงบวกต่อชุมชน | D26: • ระดับ 0: ไม่มีการดำเนินงาน • ระดับ 0.25: มีการดำเนินงานเบื้องต้น เป็นครั้งคราว • ระดับ 0.50: มีโครงการและกิจกรรมสม่ำเสมอ • ระดับ 0.75: มีโครงการที่ครอบคลุม มีการติดตามและประเมินผล • ระดับ 1.0: มีโครงการที่ยั่งยืน สร้างคุณค่าร่วมกับชุมชน มีผลลัพธ์ที่วัดได้ | G26: 1 | H26: =G26*(200/15) -> 13.333333 | I26: 1 | J26: =I26*(200/15) -> 13.333333
B27: C3.13: รายงาน CSR และการสื่อสาร (CSR Reporting & Communication) | C27: สถานประกอบการมีการดำเนินงานด้านรายงาน CSR และการสื่อสารอย่างต่อเนื่องและสร้างผลกระทบเชิงบวกต่อชุมชน | D27: • ระดับ 0: ไม่มีการดำเนินงาน • ระดับ 0.25: มีการดำเนินงานเบื้องต้น เป็นครั้งคราว • ระดับ 0.50: มีโครงการและกิจกรรมสม่ำเสมอ • ระดับ 0.75: มีโครงการที่ครอบคลุม มีการติดตามและประเมินผล • ระดับ 1.0: มีโครงการที่ยั่งยืน สร้างคุณค่าร่วมกับชุมชน มีผลลัพธ์ที่วัดได้ | G27: 1 | H27: =G27*(200/15) -> 13.333333 | I27: 1 | J27: =I27*(200/15) -> 13.333333
... B29: C3.15: โครงการอาสาสมัครพนักงาน (Employee Volunteer Program) | C29: สถานประกอบการมีการดำเนินงานด้านโครงการอาสาสมัครพนักงานอย่างต่อเนื่องและสร้างผลกระทบเชิงบวกต่อชุมชน | D29: • ระดับ 0: ไม่มีการดำเนินงาน • ระดับ 0.25: มีการดำเนินงานเบื้องต้น เป็นครั้งคราว • ระดับ 0.50: มีโครงการและกิจกรรมสม่ำเสมอ • ระดับ 0.75: มีโครงการที่ครอบคลุม มีการติดตามและประเมินผล • ระดับ 1.0: มีโครงการที่ยั่งยืน สร้างคุณค่าร่วมกับชุมชน มีผลลัพธ์ที่วัดได้ | G29: 1 | H29: =G29*(200/15) -> 13.333333 | I29: 1 | J29: =I29*(200/15) -> 13.333333
D30: รวม คะแนน | G30: =SUM(G15:G29) -> 15 | H30: =SUM(H15:H29) -> 200 | I30: =SUM(I15:I29) -> 15 | J30: =SUM(J15:J29) -> 200

Sheet ส่วนที่ 3 (M)
A1: Pillar 4: Management & Sustainability (M4)
A4: การประเมินผลการดำเนินการ (ประกอบด้วย จำนวน 15 ตัวชี้วัด / น้ำหนักคะแนน 200 คะแนน) | D4: กรอบแนวคิด : มุ่งเน้นการบริหารจัดการองค์กรแบบบูรณาการที่เชื่อมโยงกับกลยุทธ์ระยะยาว ตามหลักการ ESG (Environmental, Social, and Governance) และ GRI Standards (Global Reporting Initiative) เพื่อความโปร่งใส ตรวจสอบได้ และยั่งยืน
A7: สรุปผลคะแนน
A8: Management & Sustainability (M4) - การบริหารจัดการและความยั่งยืน (คะแนนเต็ม = 200 คะแนน)
B9: คะแนนที่ได้ : | C9: =H30 -> 200
B10: ร้อยละ (%) : | C10: =(C9/200)*100 -> 100
E13: การประเมินโดยตนเอง | I13: การประเมินโดยกรรมการ
A14: ตัวชี้วัด | B14: เกณฑ์ | C14: คำอธิบายตัวชี้วัด | D14: เกณฑ์การประเมิน | E14: ผลการดำเนินงาน | F14: หลักฐานประกอบ | G14: ระดับการประเมินตนเอง | H14: คะแนนที่ได้ | I14: ระดับการประเมินจากกรรมการ | J14: คะแนนที่ได้ | K14: ข้อเสนอแนะในการพัฒนา
A15: Pillar 4: Management & Sustainability (M4) - การบริหารจัดการและความยั่งยืน | B15: M4.1: ภาวะผู้นำและความมุ่งมั่นของผู้บริหาร (Leadership & Commitment) | C15: สถานประกอบการมีระบบบริหารจัดการด้านภาวะผู้นำและความมุ่งมั่นของผู้บริหารที่มีประสิทธิภาพและสนับสนุนการพัฒนาที่ยั่งยืน | D15: • ระดับ 0: ไม่มีระบบหรือการดำเนินการ • ระดับ 0.25: มีระบบเบื้องต้น แต่ยังไม่เป็นทางการ • ระดับ 0.50: มีระบบที่เป็นทางการ มีการดำเนินงานอย่างสม่ำเสมอ • ระดับ 0.75: มีระบบที่มีประสิทธิภาพ มีการติดตามและปรับปรุง • ระดับ 1.0: มีระบบที่เป็นเลิศ บูรณาการทั้งองค์กร มีการพัฒนาต่อเนื่อง | G15: 1 | H15: =G15*(200/15) -> 13.333333 | I15: 1 | J15: =I15*(200/15) -> 13.333333
B16: M4.2: โครงสร้างองค์กรและบทบาทหน้าที่ (Organizational Structure) | C16: สถานประกอบการมีระบบบริหารจัดการด้านโครงสร้างองค์กรและบทบาทหน้าที่ที่มีประสิทธิภาพและสนับสนุนการพัฒนาที่ยั่งยืน | D16: • ระดับ 0: ไม่มีระบบหรือการดำเนินการ • ระดับ 0.25: มีระบบเบื้องต้น แต่ยังไม่เป็นทางการ • ระดับ 0.50: มีระบบที่เป็นทางการ มีการดำเนินงานอย่างสม่ำเสมอ • ระดับ 0.75: มีระบบที่มีประสิทธิภาพ มีการติดตามและปรับปรุง • ระดับ 1.0: มีระบบที่เป็นเลิศ บูรณาการทั้งองค์กร มีการพัฒนาต่อเนื่อง | G16: 1 | H16: =G16*(200/15) -> 13.333333 | I16: 1 | J16: =I16*(200/15) -> 13.333333
B17: M4.3: ระบบบูรณาการและเชื่อมโยงยุทธศาสตร์ (Strategic Integration) | C17: สถานประกอบการมีระบบบริหารจัดการด้านระบบบูรณาการและเชื่อมโยงยุทธศาสตร์ที่มีประสิทธิภาพและสนับสนุนการพัฒนาที่ยั่งยืน | D17: • ระดับ 0: ไม่มีระบบหรือการดำเนินการ • ระดับ 0.25: มีระบบเบื้องต้น แต่ยังไม่เป็นทางการ • ระดับ 0.50: มีระบบที่เป็นทางการ มีการดำเนินงานอย่างสม่ำเสมอ • ระดับ 0.75: มีระบบที่มีประสิทธิภาพ มีการติดตามและปรับปรุง • ระดับ 1.0: มีระบบที่เป็นเลิศ บูรณาการทั้งองค์กร มีการพัฒนาต่อเนื่อง | G17: 1 | H17: =G17*(200/15) -> 13.333333 | I17: 1 | J17: =I17*(200/15) -> 13.333333
B18: M4.4: ระบบ KPI และ Dashboard (KPI Dashboard System) | C18: สถานประกอบการมีระบบบริหารจัดการด้านระบบ KPI และ Dashboardที่มีประสิทธิภาพและสนับสนุนการพัฒนาที่ยั่งยืน | D18: • ระดับ 0: ไม่มีระบบหรือการดำเนินการ • ระดับ 0.25: มีระบบเบื้องต้น แต่ยังไม่เป็นทางการ • ระดับ 0.50: มีระบบที่เป็นทางการ มีการดำเนินงานอย่างสม่ำเสมอ • ระดับ 0.75: มีระบบที่มีประสิทธิภาพ มีการติดตามและปรับปรุง • ระดับ 1.0: มีระบบที่เป็นเลิศ บูรณาการทั้งองค์กร มีการพัฒนาต่อเนื่อง | G18: 1 | H18: =G18*(200/15) -> 13.333333 | I18: 1 | J18: =I18*(200/15) -> 13.333333
B19: M4.5: การประเมินผลและติดตาม (M&E) (Monitoring & Evaluation) | C19: สถานประกอบการมีระบบบริหารจัดการด้านการประเมินผลและติดตาม (M&E)ที่มีประสิทธิภาพและสนับสนุนการพัฒนาที่ยั่งยืน | D19: • ระดับ 0: ไม่มีระบบหรือการดำเนินการ • ระดับ 0.25: มีระบบเบื้องต้น แต่ยังไม่เป็นทางการ • ระดับ 0.50: มีระบบที่เป็นทางการ มีการดำเนินงานอย่างสม่ำเสมอ • ระดับ 0.75: มีระบบที่มีประสิทธิภาพ มีการติดตามและปรับปรุง • ระดับ 1.0: มีระบบที่เป็นเลิศ บูรณาการทั้งองค์กร มีการพัฒนาต่อเนื่อง | G19: 1 | H19: =G19*(200/15) -> 13.333333 | I19: 1 | J19: =I19*(200/15) -> 13.333333
B20: M4.6: การบริหารความเสี่ยงองค์กร (ERM) (Enterprise Risk Management) | C20: สถานประกอบการมีระบบบริหารจัดการด้านการบริหารความเสี่ยงองค์กร (ERM)ที่มีประสิทธิภาพและสนับสนุนการพัฒนาที่ยั่งยืน | D20: • ระดับ 0: ไม่มีระบบหรือการดำเนินการ • ระดับ 0.25: มีระบบเบื้องต้น แต่ยังไม่เป็นทางการ • ระดับ 0.50: มีระบบที่เป็นทางการ มีการดำเนินงานอย่างสม่ำเสมอ • ระดับ 0.75: มีระบบที่มีประสิทธิภาพ มีการติดตามและปรับปรุง • ระดับ 1.0: มีระบบที่เป็นเลิศ บูรณาการทั้งองค์กร มีการพัฒนาต่อเนื่อง | G20: 1 | H20: =G20*(200/15) -> 13.333333 | I20: 1 | J20: =I20*(200/15) -> 13.333333
B21: M4.7: การปฏิบัติตามจริยธรรมและธรรมาภิบาล (Compliance & Ethics) | C21: สถานประกอบการมีระบบบริหารจัดการด้านการปฏิบัติตามจริยธรรมและธรรมาภิบาลที่มีประสิทธิภาพและสนับสนุนการพัฒนาที่ยั่งยืน | D21: • ระดับ 0: ไม่มีระบบหรือการดำเนินการ • ระดับ 0.25: มีระบบเบื้องต้น แต่ยังไม่เป็นทางการ • ระดับ 0.50: มีระบบที่เป็นทางการ มีการดำเนินงานอย่างสม่ำเสมอ • ระดับ 0.75: มีระบบที่มีประสิทธิภาพ มีการติดตามและปรับปรุง • ระดับ 1.0: มีระบบที่เป็นเลิศ บูรณาการทั้งองค์กร มีการพัฒนาต่อเนื่อง | G21: 1 | H21: =G21*(200/15) -> 13.333333 | I21: 1 | J21: =I21*(200/15) -> 13.333333
B22: M4.8: การพัฒนาศักยภาพบุคลากร (Capacity Building) | C22: สถานประกอบการมีระบบบริหารจัดการด้านการพัฒนาศักยภาพบุคลากรที่มีประสิทธิภาพและสนับสนุนการพัฒนาที่ยั่งยืน | D22: • ระดับ 0: ไม่มีระบบหรือการดำเนินการ • ระดับ 0.25: มีระบบเบื้องต้น แต่ยังไม่เป็นทางการ • ระดับ 0.50: มีระบบที่เป็นทางการ มีการดำเนินงานอย่างสม่ำเสมอ • ระดับ 0.75: มีระบบที่มีประสิทธิภาพ มีการติดตามและปรับปรุง • ระดับ 1.0: มีระบบที่เป็นเลิศ บูรณาการทั้งองค์กร มีการพัฒนาต่อเนื่อง | G22: 1 | H22: =G22*(200/15) -> 13.333333 | I22: 1 | J22: =I22*(200/15) -> 13.333333
B23: M4.9: การคุ้มครองข้อมูลสุขภาพ (PDPA) (Health Data Privacy) | C23: สถานประกอบการมีระบบบริหารจัดการด้านการคุ้มครองข้อมูลสุขภาพ (PDPA)ที่มีประสิทธิภาพและสนับสนุนการพัฒนาที่ยั่งยืน | D23: • ระดับ 0: ไม่มีระบบหรือการดำเนินการ • ระดับ 0.25: มีระบบเบื้องต้น แต่ยังไม่เป็นทางการ • ระดับ 0.50: มีระบบที่เป็นทางการ มีการดำเนินงานอย่างสม่ำเสมอ • ระดับ 0.75: มีระบบที่มีประสิทธิภาพ มีการติดตามและปรับปรุง • ระดับ 1.0: มีระบบที่เป็นเลิศ บูรณาการทั้งองค์กร มีการพัฒนาต่อเนื่อง | G23: 1 | H23: =G23*(200/15) -> 13.333333 | I23: 1 | J23: =I23*(200/15) -> 13.333333
B24: M4.10: นวัตกรรมสุขภาพและความปลอดภัย (Health & Safety Innovation) | C24: สถานประกอบการมีระบบบริหารจัดการด้านนวัตกรรมสุขภาพและความปลอดภัยที่มีประสิทธิภาพและสนับสนุนการพัฒนาที่ยั่งยืน | D24: • ระดับ 0: ไม่มีระบบหรือการดำเนินการ • ระดับ 0.25: มีระบบเบื้องต้น แต่ยังไม่เป็นทางการ • ระดับ 0.50: มีระบบที่เป็นทางการ มีการดำเนินงานอย่างสม่ำเสมอ • ระดับ 0.75: มีระบบที่มีประสิทธิภาพ มีการติดตามและปรับปรุง • ระดับ 1.0: มีระบบที่เป็นเลิศ บูรณาการทั้งองค์กร มีการพัฒนาต่อเนื่อง | G24: 1 | H24: =G24*(200/15) -> 13.333333 | I24: 1 | J24: =I24*(200/15) -> 13.333333
B25: M4.11: ระบบรางวัลและแรงจูงใจ (Reward & Incentive System) | C25: สถานประกอบการมีระบบบริหารจัดการด้านระบบรางวัลและแรงจูงใจที่มีประสิทธิภาพและสนับสนุนการพัฒนาที่ยั่งยืน | D25: • ระดับ 0: ไม่มีระบบหรือการดำเนินการ • ระดับ 0.25: มีระบบเบื้องต้น แต่ยังไม่เป็นทางการ • ระดับ 0.50: มีระบบที่เป็นทางการ มีการดำเนินงานอย่างสม่ำเสมอ • ระดับ 0.75: มีระบบที่มีประสิทธิภาพ มีการติดตามและปรับปรุง • ระดับ 1.0: มีระบบที่เป็นเลิศ บูรณาการทั้งองค์กร มีการพัฒนาต่อเนื่อง | G25: 1 | H25: =G25*(200/15) -> 13.333333 | I25: 1 | J25: =I25*(200/15) -> 13.333333
B26: M4.12: งบประมาณและการจัดสรรทรัพยากร (Budget & Resource Allocation) | C26: สถานประกอบการมีระบบบริหารจัดการด้านงบประมาณและการจัดสรรทรัพยากรที่มีประสิทธิภาพและสนับสนุนการพัฒนาที่ยั่งยืน | D26: • ระดับ 0: ไม่มีระบบหรือการดำเนินการ • ระดับ 0.25: มีระบบเบื้องต้น แต่ยังไม่เป็นทางการ • ระดับ 0.50: มีระบบที่เป็นทางการ มีการดำเนินงานอย่างสม่ำเสมอ • ระดับ 0.75: มีระบบที่มีประสิทธิภาพ มีการติดตามและปรับปรุง • ระดับ 1.0: มีระบบที่เป็นเลิศ บูรณาการทั้งองค์กร มีการพัฒนาต่อเนื่อง | G26: 1 | H26: =G26*(200/15) -> 13.333333 | I26: 1 | J26: =I26*(200/15) -> 13.333333
B27: M4.13: การสื่อสารและการมีส่วนร่วมของพนักงาน (Communication & Engagement) | C27: สถานประกอบการมีระบบบริหารจัดการด้านการสื่อสารและการมีส่วนร่วมของพนักงานที่มีประสิทธิภาพและสนับสนุนการพัฒนาที่ยั่งยืน | D27: • ระดับ 0: ไม่มีระบบหรือการดำเนินการ • ระดับ 0.25: มีระบบเบื้องต้น แต่ยังไม่เป็นทางการ • ระดับ 0.50: มีระบบที่เป็นทางการ มีการดำเนินงานอย่างสม่ำเสมอ • ระดับ 0.75: มีระบบที่มีประสิทธิภาพ มีการติดตามและปรับปรุง • ระดับ 1.0: มีระบบที่เป็นเลิศ บูรณาการทั้งองค์กร มีการพัฒนาต่อเนื่อง | G27: 1 | H27: =G27*(200/15) -> 13.333333 | I27: 1 | J27: =I27*(200/15) -> 13.333333
... B29: M4.15: การปรับปรุงอย่างต่อเนื่อง (CI) (Continuous Improvement) | C29: สถานประกอบการมีระบบบริหารจัดการด้านการปรับปรุงอย่างต่อเนื่อง (CI)ที่มีประสิทธิภาพและสนับสนุนการพัฒนาที่ยั่งยืน | D29: • ระดับ 0: ไม่มีระบบหรือการดำเนินการ • ระดับ 0.25: มีระบบเบื้องต้น แต่ยังไม่เป็นทางการ • ระดับ 0.50: มีระบบที่เป็นทางการ มีการดำเนินงานอย่างสม่ำเสมอ • ระดับ 0.75: มีระบบที่มีประสิทธิภาพ มีการติดตามและปรับปรุง • ระดับ 1.0: มีระบบที่เป็นเลิศ บูรณาการทั้งองค์กร มีการพัฒนาต่อเนื่อง | G29: 1 | H29: =G29*(200/15) -> 13.333333 | I29: 1 | J29: =I29*(200/15) -> 13.333333
D30: รวม คะแนน | G30: =SUM(G15:G29) -> 15 | H30: =SUM(H15:H29) -> 200 | I30: =SUM(I15:I29) -> 15 | J30: =SUM(J15:J29) -> 200

Sheet สรุปผล
A1: สรุปผลการประเมิน HICM V2025
A2: ตารางสรุปคะแนนแต่ละ Pillar
A3: Pillar | B3: จำนวนตัวชี้วัด | C3: คะแนนรวม (ไม่ปรับสัดส่วน)
A4: Pillar 1: Health Promotion | B4: 15 | C4: ='ส่วนที่ 3 (H)'!C9 -> 250 | D4: / 300
A5: Pillar 2: Safety & Environment | B5: 15 | C5: ='ส่วนที่ 3 (I)'!C9 -> 50 | D5: / 300
A6: Pillar 3: Community Engagement | B6: 15 | C6: ='ส่วนที่ 3 (C)'!C9 -> 200 | D6: / 200
A7: Pillar 4: Management & Sustainability | B7: 15 | C7: ='ส่วนที่ 3 (M)'!C9 -> 200 | D7: / 200
A8: รวมทั้งหมด | B8: 60 | C8: =SUM(C4:C7) -> 700 | D8: / 1,000
A10: ระดับการรับรอง (HICM Recognition Level)
A11: ระดับ | B11: คะแนน | C11: ชื่อระดับและความหมาย
A12: Level 5 | B12: 900-1000 | C12: ระดับโลก (World-Class) - องค์กรมีมาตรฐานระดับสากล เป็นต้นแบบแห่งการเรียนรู้
A13: Level 4 | B13: 800-899 | C13: เป็นเลิศ (Excellence) - องค์กรมีมาตรฐานสูง เป็นแบบอย่างที่ดี
A14: Level 3 | B14: 700-799 | C14: พัฒนาดี (Performing) - องค์กรมีระบบที่ดี มีการดำเนินงานอย่างมีประสิทธิภาพ
A15: Level 2 | B15: 600-699 | C15: กำลังพัฒนา (Developing) - องค์กรมีระบบพื้นฐานครบ กำลังพัฒนาให้ครอบคลุม
A16: Level 1 | B16: < 600 | C16: เริ่มต้น (Emerging) - องค์กรเริ่มให้ความสำคัญกับสุขภาวะ มีพื้นฐานบางส่วน
A18: ผลการประเมินขององค์กร : (เต็ม 1,000 คะแนน) | B18: =C8 -> 700 | C18: คะแนน
A20: ระดับที่ได้รับ : | B20: =if(B18<=600,A16,if(B18<=699,A15,if(B18<=799,A14,if(B18<=899,A13,if(B18<=1000,A12,"NO"))))) -> Level 3 | C20: : | D20: =if(B18<=600,C16,if(B18<=699,C15,if(B18<=799,C14,if(B18<=899,C13,if(B18<=1000,C12,"NO"))))) -> พัฒนาดี (Performing) - องค์กรมีระบบที่ดี มีการดำเนินงานอย่างมีประสิทธิภาพ
A24: ลายเซ็นผู้ประเมิน
A25: ลายเซ็นผู้ประเมิน: _______________________ | E25: ลายเซ็นผู้รับการประเมิน: _______________________
A26: ชื่อ: _____________________________________ | E26: ชื่อ: _____________________________________
A27: วันที่: _____ / _____ / _____ | E27: วันที่: _____ / _____ / _____

Sheet ส่วนที่ 4
A3: ส่วนที่ 4: แบบฟอร์มการประเมินและสรุปผล
B5: ส่วนนี้เป็นแบบฟอร์มสำหรับการบันทึกผลการประเมินและสรุปคะแนนรวม เพื่อจัดระดับสถานประกอบการตามเกณฑ์ HICM V2025
A7: ข้อมูลพื้นฐานสถานประกอบการ
B8: ชื่อสถานประกอบการ :
B9: ที่อยู่ :
B10: ประเภทอุตสาหกรรม :
B11: จำนวนพนักงาน :
B12: ผู้ประเมิน :
B13: ตำแหน่ง :
B14: วันที่ประเมิน :
B15: รอบการประเมิน :
A17: สรุปผลคะแนนแต่ละ Pillar
C19: Pillar | D19: คะแนนเต็ม | E19: คะแนนที่ได้ | F19: ร้อยละ (%)
C20: H1: Health Promotion | D20: 300 | E20: ='ส่วนที่ 3 (H)'!J31 -> 290 | F20: =(E20/D20)*100 -> 96.666667
C21: I2: Industrial Safety & Environment | D21: 300 | E21: ='ส่วนที่ 3 (I)'!K30 -> 40 | F21: =(E21/D21)*100 -> 13.333333
C22: C3: Community Engagement | D22: 200 | E22: ='ส่วนที่ 3 (C)'!J30 -> 200 | F22: =(E22/D22)*100 -> 100
C23: M4: Management & Sustainability | D23: 200 | E23: ='ส่วนที่ 3 (M)'!J30 -> 200 | F23: =(E23/D23)*100 -> 100
C24: รวมคะแนนทั้งหมด | D24: 1000 | E24: =SUM(E20:E23) -> 730 | F24: =(E24/D24)*100 -> 73
A26: ระดับการรับรอง HICM
C27: ระดับ | D27: คะแนน | E27: ผลการประเมิน
C28: Level 1: เริ่มต้น (Emerging) | D28: < 600 | E28: =if(E24<=600,C28,if(E24<=699,C29,if(E24<=799,C30,if(E24<=899,C31,if(E24<=1000,C32,"NO"))))) -> Level 3: พัฒนาดี (Performing)
C29: Level 2: กำลังพัฒนา (Developing) | D29: 600-699
C30: Level 3: พัฒนาดี (Performing) | D30: 700-799
C31: Level 4: เป็นเลิศ (Excellence) | D31: 800-899
C32: Level 5: ระดับโลก (World-Class) | D32: 900-1000
A35: วิเคราะห์จุดแข็งและจุดที่ควรพัฒนา
B38: จุดแข็ง (Strengths)
C39: 1) 2) 3)
B43: จุดที่ควรพัฒนา (Areas for Improvement)
C44: 1) 2) 3)
A49: แผนการพัฒนาในรอบถัดไป
B51: ลำดับ | C51: กิจกรรม/โครงการ | D51: ผู้รับผิดชอบ | E51: ระยะเวลา | F51: งบประมาณ
B52: 1
B53: 2
B54: 3
B55: 4
B56: 5
B58: ลายเซ็นผู้ประเมินและผู้อนุมัติ
B60: ผู้ประเมิน: | D60: วันที่:
B61: ผู้ตรวจสอบ: | D61: วันที่:
...
